<robot name="upper_arm">

    <material name="color">
        <color rgba="0 1 0 1"/>
    </material>

    <link name="camera_depth_optical_frame"/>

    <joint name="world_to_shoulder" type="fixed">
        <parent link="camera_depth_optical_frame"/>
        <child link="RightShoulder"/>
        <origin xyz="-0.05723638 -0.11301016  1.0710001" rpy="3.14 1.57 0"/>
    </joint>

    <!--  shoudler, 3DOF -->
    <link name="RightShoulder">
       

        <visual>
			<!--box origin wrt jRightC7Shoulder. RPY rotated of pi/2.-->
            <origin xyz="0 0 0" rpy="0 0 0" />
            <geometry>
                <sphere radius="0.05"/>
            </geometry>
            <material name="color"/>
        </visual>
    </link>

    <joint name="jRightShoulder_rotx" type="revolute">
        <origin xyz="0 0 0" rpy="0 0 0"/>
        <parent link="RightShoulder"/>
        <child link="RightUpperArm_f1"/>
        <dynamics damping="0.1" friction="0.0"/>
        <limit effort="30" velocity="1.0" lower="-2.35619" upper="1.5708" />
        <axis xyz="1 0 0" />
    </joint>

    <link name="RightUpperArm_f1">
        <inertial>
            <mass value="0"/>
            <origin xyz="0 0 0" rpy="0 0 0" />
            <inertia ixx="0" iyy="0" izz="0" ixy="0" ixz="0" iyz="0"/>
        </inertial>
    </link>

    <joint name="jRightShoulder_rotz" type="revolute">
        <origin xyz="0 0 0" rpy="0 0 0"/>
        <parent link="RightUpperArm_f1"/>
        <child link="RightUpperArm_f2"/>
        <dynamics damping="0.1" friction="0.0"/>
        <limit effort="30" velocity="1.0" lower="-0.785398" upper="3.14159" />
        <axis xyz="0 0 1" />
    </joint>
    
    <link name="RightUpperArm_f2">
        <inertial>
            <mass value="0"/>
            <origin xyz="0 0 0" rpy="0 0 0" />
            <inertia ixx="0" iyy="0" izz="0" ixy="0" ixz="0" iyz="0"/>
        </inertial>
    </link>

    <joint name="jRightShoulder_roty" type="revolute">
        <origin xyz="0 0 0" rpy="0 0 0"/>
        <parent link="RightUpperArm_f2"/>
        <child link="RightUpperArm"/>
        <dynamics damping="0.1" friction="0.0"/>
        <limit effort="30" velocity="1.0" lower="-1.5708" upper="1.5708" />
        <axis xyz="0 1 0" />
    </joint>

    <!-- elbow, 3 dof -->
    <link name="RightUpperArm">
        <inertial>
            <mass value="2.181"/>
			<!--COM origin wrt jRightShoulder-->
            <origin xyz="0    -0.16437           0" rpy="0 0 0" />
            <inertia ixx="0.020332" iyy="0.0013806" izz="0.020332" ixy="0" ixz="0" iyz="0"/>
        </inertial>

        <visual>
			<!--box origin wrt jRightShoulder. RPY rotated of pi/2.-->
            <origin xyz="0    -0.16437           0" rpy="1.5708 0 0" />
            <geometry>
                <cylinder length="0.2" radius="0.035581"/>
            </geometry>
            <material name="color"/>
        </visual>

        <collision>
			<!--box origin wrt jRightShoulder. RPY rotated of pi/2.-->
            <origin xyz="0    -0.16437           0" rpy="1.5708 0 0" />
            <geometry>
                <cylinder length="0.24" radius="0.035581"/>
            </geometry>
        </collision>

    </link>

    <joint name="jRightElbow_rotz" type="revolute">
        <origin xyz="0 -0.24 0" rpy="0 0 0"/>
        <parent link="RightUpperArm"/>
        <child link="RightForeArm"/>
        <dynamics damping="0.1" friction="0.0"/>
        <limit effort="30" velocity="1.0" lower="0" upper="2.53073" />
        <axis xyz="0 0 1" />
    </joint>

    <link name="RightForeArm">
        <inertial>
            <mass value="1.454"/>
			<!--COM origin wrt jRightElbow-->
            <origin xyz="0    -0.135           0" rpy="0 0 0" />
            <inertia ixx="0.008948" iyy="0.00040906" izz="0.008948" ixy="0" ixz="0" iyz="0"/>
        </inertial>

        <visual>
			<!--box origin wrt jRightElbow. RPY rotated of pi/2.-->
            <origin xyz="0    -0.135           0" rpy="1.5708 0 0" />
            <geometry>
                <cylinder length="0.27" radius="0.023721"/>
            </geometry>
            <material name="color"/>
        </visual>

        <collision>
			<!--box origin wrt jRightElbow. RPY rotated of pi/2.-->
            <origin xyz="0    -0.135           0" rpy="1.5708 0 0" />
            <geometry>
                <cylinder length="0.27" radius="0.023721"/>
            </geometry>
        </collision>

    </link>
    
    <joint name="jRightElbow_roty" type="revolute">
        <origin xyz="0 -0.27 0" rpy="0 0 0"/>
        <parent link="RightForeArm"/>
        <child link="RightForeArm_f1"/>
        <dynamics damping="0.1" friction="0.0"/>
        <limit effort="30" velocity="1.0" lower="-1.5708" upper="1.48353" />
        <axis xyz="0 1 0" />
    </joint>

    <link name="RightForeArm_f1">
        <inertial>
            <mass value="0"/>
            <origin xyz="0 0 0" rpy="0 0 0" />
            <inertia ixx="0" iyy="0" izz="0" ixy="0" ixz="0" iyz="0"/>
        </inertial>
    </link>

    <!-- wrist 2 dofs -->
    <joint name="jRightWrist_rotx" type="revolute">
        <origin xyz="0    0  0" rpy="0 0 0"/>
        <parent link="RightForeArm_f1"/>
        <child link="RightHand_f1"/>
        <dynamics damping="0.1" friction="0.0"/>
        <limit effort="30" velocity="1.0" lower="-0.872665" upper="1.0472" />
        <axis xyz="1 0 0" />
    </joint>

    <link name="RightHand_f1">
        <inertial>
            <mass value="0"/>
            <origin xyz="0 0 0" rpy="0 0 0" />
            <inertia ixx="0" iyy="0" izz="0" ixy="0" ixz="0" iyz="0"/>
        </inertial>
    </link>

    <joint name="jRightWrist_rotz" type="revolute">
        <origin xyz="0 0 0" rpy="0 0 0"/>
        <parent link="RightHand_f1"/>
        <child link="RightHand"/>
        <dynamics damping="0.1" friction="0.0"/>
        <limit effort="30" velocity="1.0" lower="-0.523599" upper="0.349066" />
        <axis xyz="0 0 1" />
    </joint>

    <link name="RightHand">
        <inertial>
            <mass value="0.4362"/>
			<!--COM origin wrt jRightWrist-->
            <origin xyz="0    -0.05           0" rpy="0 0 0" />
            <inertia ixx="0.0015471" iyy="0.00073303" izz="0.0021165" ixy="0" ixz="0" iyz="0"/>
        </inertial>

        <visual>
			<!--box origin wrt jRightWrist-->
            <origin xyz="0    -0.05           0" rpy="0 0 0" />
            <geometry>
                <box size="0.04     0.133    0.133"/>
            </geometry>
            <material name="color"/>
        </visual>

        <collision>
			<!--box origin wrt jRightWrist-->
            <origin xyz="0    -0.05           0" rpy="0 0 0" />
            <geometry>
                <box size="0.04     0.133    0.133"/>
            </geometry>
        </collision>

    </link>
<!-- 
    <joint name="jRightHandCOM" type="fixed">
        <origin xyz="0 -0.05 0" rpy="0 0 0"/>
        <parent link="RightHand"/>
        <child link="EE_center"/>
        <axis xyz="0 0 0" />
    </joint>
  
    <link name="EE_center">
    </link> -->
       
    
<!-- End of right arm configuration -->
</robot>
